Workbook
Name 부적합건수: OFFSET('2.거래내역'!$J$12,,,COUNTA('2.거래내역'!$J$12:$J$9916))
Name 슬라이서_검사명: #N/A
Name 슬라이서_영업소명: #N/A
Name 슬라이서_영업소명1: #N/A
Name 슬라이서_접수년: #N/A
Name 슬라이서_접수년월: #N/A
Name 슬라이서_접수년월1: #N/A
Name 슬라이서_지역명: #N/A
Name 슬라이서_지역명1: #N/A
Name 접수건수: OFFSET('2.거래내역'!$I$12,,,COUNTA('2.거래내역'!$I$12:$I$9916))
Name 접수월: OFFSET('2.거래내역'!$B$11,,,COUNTA('2.거래내역'!$B$11:$B$9916),COUNTA('2.거래내역'!$B$11:$K$11))

Sheet 데이터
A2: 냉동검체의 질 관리 및 운반과정 검토 현황 | G2: 냉동검체의 질 관리 및 운반과정 검토 현황
A5: 영업소별 의뢰 현황 | G5: 검사항목별 의뢰 현황
A6: 지역 | B6: 영업소 | C6: 병원 | D6: 건수 | E6: 부적합 | F6: 부적합률(%) | G6: 검사항목별 | H6: 부적합건수 | I6: 부적합(%) | J6: 접수건수 | K6: 접수비율(%)
A7: =RAW!$H3 -> 충남 | B7: =RAW!$I3 -> 오창 | C7: =RAW!$J3 -> 키우리소아청소년과의원 | D7: =RAW!$K3 -> 1238 | E7: =RAW!$L3 -> 1230 | F7: =RAW!$M3 -> 99.353796 | G7: ACTH | H7: 3769 | I7: =H7/J7 -> 0.27424871 | J7: 13743 | K7: =J7/$J$9 -> 0.91558961
A8: =RAW!$H4 -> 경북 | B8: =RAW!$I4 -> 경주 | C8: =RAW!$J4 -> 바른몸의원 | D8: =RAW!$K4 -> 713 | E8: =RAW!$L4 -> 705 | F8: =RAW!$M4 -> 98.87798 | G8: Ammonia | H8: 892 | I8: =H8/J8 -> 0.70402526 | J8: 1267 | K8: =J8/$J$9 -> 0.084410393
A9: =RAW!$H5 -> 경북 | B9: =RAW!$I5 -> 경주 | C9: =RAW!$J5 -> 굿모닝병원 | D9: =RAW!$K5 -> 353 | E9: =RAW!$L5 -> 325 | F9: =RAW!$M5 -> 92.067989 | G9: 총합계 | H9: 4661 | I9: =H9/J9 -> 0.31052632 | J9: 15010 | K9: =SUM(K7:K8) -> 1
A10: =RAW!$H6 -> 인천 | B10: =RAW!$I6 -> 인천 | C10: =RAW!$J6 -> 인천터미널 정형외과의원 | D10: =RAW!$K6 -> 291 | E10: =RAW!$L6 -> 290 | F10: =RAW!$M6 -> 99.656357
A11: =RAW!$H7 -> 경남 | B11: =RAW!$I7 -> 울산중부 | C11: =RAW!$J7 -> 울산병원 | D11: =RAW!$K7 -> 272 | E11: =RAW!$L7 -> 259 | F11: =RAW!$M7 -> 95.220588 | G11: 지역별 의뢰 현황
A12: =RAW!$H8 -> 인천 | B12: =RAW!$I8 -> 인천 | C12: =RAW!$J8 -> 현대의원(동춘동) | D12: =RAW!$K8 -> 333 | E12: =RAW!$L8 -> 211 | F12: =RAW!$M8 -> 63.363363 | G12: 지역별 | H12: 부적합건수 | I12: 부적합(%) | J12: 접수건수 | K12: 접수비율(%)
A13: =RAW!$H9 -> 서울 | B13: =RAW!$I9 -> 서울중부 | C13: =RAW!$J9 -> 서울케이(K)내과의원 | D13: =RAW!$K9 -> 266 | E13: =RAW!$L9 -> 185 | F13: =RAW!$M9 -> 69.548872 | G13: 경기 | H13: 105 | I13: =H13/J13 -> 0.12152778 | J13: 864 | K13: =J13/$J$25 -> 0.057561626
A14: =RAW!$H10 -> 경북 | B14: =RAW!$I10 -> 대구남부 | C14: =RAW!$J10 -> 청춘내과의원 | D14: =RAW!$K10 -> 174 | E14: =RAW!$L10 -> 170 | F14: =RAW!$M10 -> 97.701149 | G14: 경남 | H14: 419 | I14: =H14/J14 -> 0.21948664 | J14: 1909 | K14: =J14/$J$25 -> 0.12718188
A15: =RAW!$H11 -> 경북 | B15: =RAW!$I11 -> 대구서부 | C15: =RAW!$J11 -> 대구보훈병원 | D15: =RAW!$K11 -> 160 | E15: =RAW!$L11 -> 155 | F15: =RAW!$M11 -> 96.875 | G15: 경북 | H15: 1697 | I15: =H15/J15 -> 0.36835251 | J15: 4607 | K15: =J15/$J$25 -> 0.30692871
A16: =RAW!$H12 -> 경북 | B16: =RAW!$I12 -> 대구남부 | C16: =RAW!$J12 -> 서대구대동병원 | D16: =RAW!$K12 -> 157 | E16: =RAW!$L12 -> 121 | F16: =RAW!$M12 -> 77.070064 | G16: 서울 | H16: 355 | I16: =H16/J16 -> 0.168486 | J16: 2107 | K16: =J16/$J$25 -> 0.14037308
A17: =RAW!$H13 -> 영서 | B17: =RAW!$I13 -> 원주 | C17: =RAW!$J13 -> 명지병원(제천) | D17: =RAW!$K13 -> 109 | E17: =RAW!$L13 -> 108 | F17: =RAW!$M13 -> 99.082569 | G17: 영동 | H17: 0 | I17: =H17/J17 -> 0 | J17: 21 | K17: =J17/$J$25 -> 0.0013990673
A18: =RAW!$H14 -> 서울 | B18: =RAW!$I14 -> 서울중부 | C18: =RAW!$J14 -> 의료법인 소화병원 | D18: =RAW!$K14 -> 243 | E18: =RAW!$L14 -> 86 | F18: =RAW!$M14 -> 35.390947 | G18: 영서 | H18: 125 | I18: =H18/J18 -> 0.46816479 | J18: 267 | K18: =J18/$J$25 -> 0.017788141
A19: =RAW!$H15 -> 충남 | B19: =RAW!$I15 -> 세종(출) | C19: =RAW!$J15 -> 유앤이내과 | D19: =RAW!$K15 -> 272 | E19: =RAW!$L15 -> 63 | F19: =RAW!$M15 -> 23.161765 | G19: 인천 | H19: 547 | I19: =H19/J19 -> 0.62585812 | J19: 874 | K19: =J19/$J$25 -> 0.058227848
A20: =RAW!$H16 -> 경북 | B20: =RAW!$I16 -> 대구서부 | C20: =RAW!$J16 -> 한솔요양병원 | D20: =RAW!$K16 -> 45 | E20: =RAW!$L16 -> 45 | F20: =RAW!$M16 -> 100 | G20: 전남 | H20: 39 | I20: =H20/J20 -> 0.040794979 | J20: 956 | K20: =J20/$J$25 -> 0.063690873
A21: =RAW!$H17 -> 경남 | B21: =RAW!$I17 -> 진주 | C21: =RAW!$J17 -> SAM CHEON PO JEIL HOSPITAL | D21: =RAW!$K17 -> 455 | E21: =RAW!$L17 -> 43 | F21: =RAW!$M17 -> 9.4505495 | G21: 전북 | H21: 49 | I21: =H21/J21 -> 0.22897196 | J21: 214 | K21: =J21/$J$25 -> 0.014257162
A22: =RAW!$H18 -> 경북 | B22: =RAW!$I18 -> 대구남부 | C22: =RAW!$J18 -> 우리내과의원 | D22: =RAW!$K18 -> 155 | E22: =RAW!$L18 -> 32 | F22: =RAW!$M18 -> 20.645161 | G22: 제주 | H22: 1 | I22: =H22/J22 -> 0.002173913 | J22: 460 | K22: =J22/$J$25 -> 0.030646236
A23: =RAW!$H19 -> 서울 | B23: =RAW!$I19 -> 서울강남 | C23: =RAW!$J19 -> 이화의원 | D23: =RAW!$K19 -> 24 | E23: =RAW!$L19 -> 22 | F23: =RAW!$M19 -> 91.666667 | G23: 충남 | H23: 1310 | I23: =H23/J23 -> 0.49809886 | J23: 2630 | K23: =J23/$J$25 -> 0.17521652
A24: =RAW!$H20 -> 인천 | B24: =RAW!$I20 -> 인천 | C24: =RAW!$J20 -> 나누리 인천 주안병원 | D24: =RAW!$K20 -> 23 | E24: =RAW!$L20 -> 21 | F24: =RAW!$M20 -> 91.304348 | G24: 충북 | H24: 0 | I24: =H24/J24 -> 0 | J24: 81 | K24: =J24/$J$25 -> 0.0053964024
A25: =RAW!$H21 -> 경남 | B25: =RAW!$I21 -> 진주 | C25: =RAW!$J21 -> 엠마우스 요양병원 | D25: =RAW!$K21 -> 21 | E25: =RAW!$L21 -> 21 | F25: =RAW!$M21 -> 100 | G25: 총합계 | H25: 4661 | I25: =H25/J25 -> 0.31052632 | J25: 15010 | K25: =SUM(K13:K24) -> 0.99866755
A26: =RAW!$H22 -> 경남 | B26: =RAW!$I22 -> 진주 | C26: =RAW!$J22 -> 센텀병원 | D26: =RAW!$K22 -> 21 | E26: =RAW!$L22 -> 19 | F26: =RAW!$M22 -> 90.47619
A27: =RAW!$H23 -> 경기 | B27: =RAW!$I23 -> 용인 | C27: =RAW!$J23 -> 카리스요양병원 | D27: =RAW!$K23 -> 19 | E27: =RAW!$L23 -> 19 | F27: =RAW!$M23 -> 100 | G27: 주요 점검 병원
A28: =RAW!$H24 -> 경북 | B28: =RAW!$I24 -> 대구남부 | C28: =RAW!$J24 -> 대구기독병원 | D28: =RAW!$K24 -> 18 | E28: =RAW!$L24 -> 16 | F28: =RAW!$M24 -> 88.888889 | G28: 지역 | H28: 영업소 | I28: 병원명 | K28: 조치사항
A29: =RAW!$H25 -> 경북 | B29: =RAW!$I25 -> 대구남부 | C29: =RAW!$J25 -> 이상엽내과의원 | D29: =RAW!$K25 -> 16 | E29: =RAW!$L25 -> 14 | F29: =RAW!$M25 -> 87.5 | G29: =$A7 -> 충남 | H29: =$B7 -> 오창 | I29: =$C7 -> 키우리소아청소년과의원
A30: =RAW!$H26 -> 서울 | B30: =RAW!$I26 -> 서울서부 | C30: =RAW!$J26 -> 목동연세365의원 | D30: =RAW!$K26 -> 14 | E30: =RAW!$L26 -> 14 | F30: =RAW!$M26 -> 100 | G30: =$A8 -> 경북 | H30: =$B8 -> 경주 | I30: =$C8 -> 바른몸의원
A31: =RAW!$H27 -> 경북 | B31: =RAW!$I27 -> 대구남부 | C31: =RAW!$J27 -> 범어샘편한내과 | D31: =RAW!$K27 -> 27 | E31: =RAW!$L27 -> 13 | F31: =RAW!$M27 -> 48.148148 | G31: =$A9 -> 경북 | H31: =$B9 -> 경주 | I31: =$C9 -> 굿모닝병원
A32: =RAW!$H28 -> 경기 | B32: =RAW!$I28 -> 수원북부 | C32: =RAW!$J28 -> 나누리수원병원(외주) | D32: =RAW!$K28 -> 23 | E32: =RAW!$L28 -> 13 | F32: =RAW!$M28 -> 56.521739 | G32: =$A10 -> 인천 | H32: =$B10 -> 인천 | I32: =$C10 -> 인천터미널 정형외과의원
A33: =RAW!$H29 -> 경기 | B33: =RAW!$I29 -> 용인 | C33: =RAW!$J29 -> 분당21세기의원 | D33: =RAW!$K29 -> 13 | E33: =RAW!$L29 -> 13 | F33: =RAW!$M29 -> 100 | G33: =$A11 -> 경남 | H33: =$B11 -> 울산중부 | I33: =$C11 -> 울산병원
A34: =RAW!$H30 -> 인천 | B34: =RAW!$I30 -> 인천 | C34: =RAW!$J30 -> 강문호내과 | D34: =RAW!$K30 -> 12 | E34: =RAW!$L30 -> 12 | F34: =RAW!$M30 -> 100 | G34: =$A12 -> 인천 | H34: =$B12 -> 인천 | I34: =$C12 -> 현대의원(동춘동)
A35: =RAW!$H31 -> 서울 | B35: =RAW!$I31 -> 용산(출) | C35: =RAW!$J31 -> 연세중앙내과의원 | D35: =RAW!$K31 -> 15 | E35: =RAW!$L31 -> 11 | F35: =RAW!$M31 -> 73.333333 | G35: =$A13 -> 서울 | H35: =$B13 -> 서울중부 | I35: =$C13 -> 서울케이(K)내과의원
A36: =RAW!$H32 -> 경북 | B36: =RAW!$I32 -> 대구남부 | C36: =RAW!$J32 -> 용각의료재단 한신병원 | D36: =RAW!$K32 -> 14 | E36: =RAW!$L32 -> 11 | F36: =RAW!$M32 -> 78.571429 | G36: =$A14 -> 경북 | H36: =$B14 -> 대구남부 | I36: =$C14 -> 청춘내과의원
A37: =RAW!$H33 -> 전북 | B37: =RAW!$I33 -> 전북 | C37: =RAW!$J33 -> 구기선내과의원 | D37: =RAW!$K33 -> 11 | E37: =RAW!$L33 -> 11 | F37: =RAW!$M33 -> 100 | G37: =$A15 -> 경북 | H37: =$B15 -> 대구서부 | I37: =$C15 -> 대구보훈병원
A38: =RAW!$H34 -> 경남 | B38: =RAW!$I34 -> 부산중부 | C38: =RAW!$J34 -> 바른병원 | D38: =RAW!$K34 -> 18 | E38: =RAW!$L34 -> 9 | F38: =RAW!$M34 -> 50 | G38: =$A16 -> 경북 | H38: =$B16 -> 대구남부 | I38: =$C16 -> 서대구대동병원
A39: =RAW!$H35 -> 영서 | B39: =RAW!$I35 -> 영서2 | C39: =RAW!$J35 -> 건국대학교충주병원 | D39: =RAW!$K35 -> 71 | E39: =RAW!$L35 -> 8 | F39: =RAW!$M35 -> 11.267606 | G39: =$A17 -> 영서 | H39: =$B17 -> 원주 | I39: =$C17 -> 명지병원(제천)
A40: =RAW!$H36 -> 전북 | B40: =RAW!$I36 -> 전북 | C40: =RAW!$J36 -> 박은재 내과 | D40: =RAW!$K36 -> 13 | E40: =RAW!$L36 -> 8 | F40: =RAW!$M36 -> 61.538462 | G40: =$A18 -> 서울 | H40: =$B18 -> 서울중부 | I40: =$C18 -> 의료법인 소화병원
... A43: =RAW!$H39 -> 충남 | B43: =RAW!$I39 -> 천안 | C43: =RAW!$J39 -> 이수내과의원 | D43: =RAW!$K39 -> 36 | E43: =RAW!$L39 -> 7 | F43: =RAW!$M39 -> 19.444444 | G43: =$A21 -> 경남 | H43: =$B21 -> 진주 | I43: =$C21 -> SAM CHEON PO JEIL HOSPITAL
A44: =RAW!$H40 -> 전북 | B44: =RAW!$I40 -> 전북 | C44: =RAW!$J40 -> 효사랑가족요양병원 | D44: =RAW!$K40 -> 10 | E44: =RAW!$L40 -> 7 | F44: =RAW!$M40 -> 70
A45: =RAW!$H41 -> 경북 | B45: =RAW!$I41 -> 구미 | C45: =RAW!$J41 -> 참조은요양병원 | D45: =RAW!$K41 -> 7 | E45: =RAW!$L41 -> 7 | F45: =RAW!$M41 -> 100
...

Sheet RAW
B2: 영업소명 | C2: 지역별 | E2: 검사명 | F2: 부적합 | H2: 지역 | I2: 영업소명 | J2: 병원명 | K2: 전체건수 | L2: 부적합건수 | M2: 비율(%) | O2: 행 레이블 | P2: 합계 : 코멘트 입력 건수 | Q2: 합계 : 접수건수
B3: 김포 | C3: 경기 | E3: ACTH | F3: 코멘트 입력 건수 | H3: =VLOOKUP(I3,$B$2:$C$64,2,0) -> 충남 | I3: 오창 | J3: 키우리소아청소년과의원 | K3: =SUMIF('원본 (분리)'!$B$2:$B$454,J3,'원본 (분리)'!$D$2:$D$454) -> 1238 | L3: =SUMIF('원본 (분리)'!$B$2:$B$454,$J3,'원본 (분리)'!$E$2:$E$454) -> 1230 | M3: =IFERROR((L3/K3)*100,) -> 99.353796 | O3: ACTH | P3: 3765 | Q3: 13733
B4: 부천 | C4: 경기 | E4: Ammonia | F4: 리마크 입력 건수 | H4: =VLOOKUP(I4,$B$2:$C$64,2,0) -> 경북 | I4: 경주 | J4: 바른몸의원 | K4: =SUMIF('원본 (분리)'!$B$2:$B$454,J4,'원본 (분리)'!$D$2:$D$454) -> 713 | L4: =SUMIF('원본 (분리)'!$B$2:$B$454,$J4,'원본 (분리)'!$E$2:$E$454) -> 705 | M4: =IFERROR((L4/K4)*100,) -> 98.87798 | O4: Ammonia | P4: 882 | Q4: 1257
B5: 성남(출) | C5: 경기 | H5: =VLOOKUP(I5,$B$2:$C$64,2,0) -> 경북 | I5: 경주 | J5: 굿모닝병원 | K5: =SUMIF('원본 (분리)'!$B$2:$B$454,J5,'원본 (분리)'!$D$2:$D$454) -> 353 | L5: =SUMIF('원본 (분리)'!$B$2:$B$454,$J5,'원본 (분리)'!$E$2:$E$454) -> 325 | M5: =IFERROR((L5/K5)*100,) -> 92.067989 | O5: 총합계 | P5: 4647 | Q5: 14990
B6: 수원남부 | C6: 경기 | H6: =VLOOKUP(I6,$B$2:$C$64,2,0) -> 인천 | I6: 인천 | J6: 인천터미널 정형외과의원 | K6: =SUMIF('원본 (분리)'!$B$2:$B$454,J6,'원본 (분리)'!$D$2:$D$454) -> 291 | L6: =SUMIF('원본 (분리)'!$B$2:$B$454,$J6,'원본 (분리)'!$E$2:$E$454) -> 290 | M6: =IFERROR((L6/K6)*100,) -> 99.656357
B7: 수원북부 | C7: 경기 | H7: =VLOOKUP(I7,$B$2:$C$64,2,0) -> 경남 | I7: 울산중부 | J7: 울산병원 | K7: =SUMIF('원본 (분리)'!$B$2:$B$454,J7,'원본 (분리)'!$D$2:$D$454) -> 272 | L7: =SUMIF('원본 (분리)'!$B$2:$B$454,$J7,'원본 (분리)'!$E$2:$E$454) -> 259 | M7: =IFERROR((L7/K7)*100,) -> 95.220588
B8: 안산 | C8: 경기 | H8: =VLOOKUP(I8,$B$2:$C$64,2,0) -> 인천 | I8: 인천 | J8: 현대의원(동춘동) | K8: =SUMIF('원본 (분리)'!$B$2:$B$454,J8,'원본 (분리)'!$D$2:$D$454) -> 333 | L8: =SUMIF('원본 (분리)'!$B$2:$B$454,$J8,'원본 (분리)'!$E$2:$E$454) -> 211 | M8: =IFERROR((L8/K8)*100,) -> 63.363363 | O8: 행 레이블 | P8: 합계 : 부적합건수 | Q8: 합계 : 전체건수
B9: 양평(출) | C9: 경기 | H9: =VLOOKUP(I9,$B$2:$C$64,2,0) -> 서울 | I9: 서울중부 | J9: 서울케이(K)내과의원 | K9: =SUMIF('원본 (분리)'!$B$2:$B$454,J9,'원본 (분리)'!$D$2:$D$454) -> 266 | L9: =SUMIF('원본 (분리)'!$B$2:$B$454,$J9,'원본 (분리)'!$E$2:$E$454) -> 185 | M9: =IFERROR((L9/K9)*100,) -> 69.548872 | O9: 경기 | P9: 105 | Q9: 864
B10: 일산 | C10: 경기 | H10: =VLOOKUP(I10,$B$2:$C$64,2,0) -> 경북 | I10: 대구남부 | J10: 청춘내과의원 | K10: =SUMIF('원본 (분리)'!$B$2:$B$454,J10,'원본 (분리)'!$D$2:$D$454) -> 174 | L10: =SUMIF('원본 (분리)'!$B$2:$B$454,$J10,'원본 (분리)'!$E$2:$E$454) -> 170 | M10: =IFERROR((L10/K10)*100,) -> 97.701149 | O10: 경남 | P10: 419 | Q10: 1909
B11: 파주(출) | C11: 경기 | H11: =VLOOKUP(I11,$B$2:$C$64,2,0) -> 경북 | I11: 대구서부 | J11: 대구보훈병원 | K11: =SUMIF('원본 (분리)'!$B$2:$B$454,J11,'원본 (분리)'!$D$2:$D$454) -> 160 | L11: =SUMIF('원본 (분리)'!$B$2:$B$454,$J11,'원본 (분리)'!$E$2:$E$454) -> 155 | M11: =IFERROR((L11/K11)*100,) -> 96.875 | O11: 경북 | P11: 1697 | Q11: 4607
B12: 평택 | C12: 경기 | H12: =VLOOKUP(I12,$B$2:$C$64,2,0) -> 경북 | I12: 대구남부 | J12: 서대구대동병원 | K12: =SUMIF('원본 (분리)'!$B$2:$B$454,J12,'원본 (분리)'!$D$2:$D$454) -> 157 | L12: =SUMIF('원본 (분리)'!$B$2:$B$454,$J12,'원본 (분리)'!$E$2:$E$454) -> 121 | M12: =IFERROR((L12/K12)*100,) -> 77.070064 | O12: 서울 | P12: 355 | Q12: 2107
B13: 용인 | C13: 경기 | H13: =VLOOKUP(I13,$B$2:$C$64,2,0) -> 영서 | I13: 원주 | J13: 명지병원(제천) | K13: =SUMIF('원본 (분리)'!$B$2:$B$454,J13,'원본 (분리)'!$D$2:$D$454) -> 109 | L13: =SUMIF('원본 (분리)'!$B$2:$B$454,$J13,'원본 (분리)'!$E$2:$E$454) -> 108 | M13: =IFERROR((L13/K13)*100,) -> 99.082569 | O13: 영동 | P13: 0 | Q13: 21
B14: 김해 | C14: 경남 | H14: =VLOOKUP(I14,$B$2:$C$64,2,0) -> 서울 | I14: 서울중부 | J14: 의료법인 소화병원 | K14: =SUMIF('원본 (분리)'!$B$2:$B$454,J14,'원본 (분리)'!$D$2:$D$454) -> 243 | L14: =SUMIF('원본 (분리)'!$B$2:$B$454,$J14,'원본 (분리)'!$E$2:$E$454) -> 86 | M14: =IFERROR((L14/K14)*100,) -> 35.390947 | O14: 영서 | P14: 125 | Q14: 267
B15: 부산남부 | C15: 경남 | H15: =VLOOKUP(I15,$B$2:$C$64,2,0) -> 충남 | I15: 세종(출) | J15: 유앤이내과 | K15: =SUMIF('원본 (분리)'!$B$2:$B$454,J15,'원본 (분리)'!$D$2:$D$454) -> 272 | L15: =SUMIF('원본 (분리)'!$B$2:$B$454,$J15,'원본 (분리)'!$E$2:$E$454) -> 63 | M15: =IFERROR((L15/K15)*100,) -> 23.161765 | O15: 인천 | P15: 547 | Q15: 874
B16: 부산동부 | C16: 경남 | H16: =VLOOKUP(I16,$B$2:$C$64,2,0) -> 경북 | I16: 대구서부 | J16: 한솔요양병원 | K16: =SUMIF('원본 (분리)'!$B$2:$B$454,J16,'원본 (분리)'!$D$2:$D$454) -> 45 | L16: =SUMIF('원본 (분리)'!$B$2:$B$454,$J16,'원본 (분리)'!$E$2:$E$454) -> 45 | M16: =IFERROR((L16/K16)*100,) -> 100 | O16: 전남 | P16: 39 | Q16: 956
B17: 부산북부 | C17: 경남 | H17: =VLOOKUP(I17,$B$2:$C$64,2,0) -> 경남 | I17: 진주 | J17: SAM CHEON PO JEIL HOSPITAL | K17: =SUMIF('원본 (분리)'!$B$2:$B$454,J17,'원본 (분리)'!$D$2:$D$454) -> 455 | L17: =SUMIF('원본 (분리)'!$B$2:$B$454,$J17,'원본 (분리)'!$E$2:$E$454) -> 43 | M17: =IFERROR((L17/K17)*100,) -> 9.4505495 | O17: 전북 | P17: 49 | Q17: 214
B18: 부산서부 | C18: 경남 | H18: =VLOOKUP(I18,$B$2:$C$64,2,0) -> 경북 | I18: 대구남부 | J18: 우리내과의원 | K18: =SUMIF('원본 (분리)'!$B$2:$B$454,J18,'원본 (분리)'!$D$2:$D$454) -> 155 | L18: =SUMIF('원본 (분리)'!$B$2:$B$454,$J18,'원본 (분리)'!$E$2:$E$454) -> 32 | M18: =IFERROR((L18/K18)*100,) -> 20.645161 | O18: 제주 | P18: 1 | Q18: 460
B19: 부산중부 | C19: 경남 | H19: =VLOOKUP(I19,$B$2:$C$64,2,0) -> 서울 | I19: 서울강남 | J19: 이화의원 | K19: =SUMIF('원본 (분리)'!$B$2:$B$454,J19,'원본 (분리)'!$D$2:$D$454) -> 24 | L19: =SUMIF('원본 (분리)'!$B$2:$B$454,$J19,'원본 (분리)'!$E$2:$E$454) -> 22 | M19: =IFERROR((L19/K19)*100,) -> 91.666667 | O19: 충남 | P19: 1310 | Q19: 2630
B20: 울산서부 | C20: 경남 | H20: =VLOOKUP(I20,$B$2:$C$64,2,0) -> 인천 | I20: 인천 | J20: 나누리 인천 주안병원 | K20: =SUMIF('원본 (분리)'!$B$2:$B$454,J20,'원본 (분리)'!$D$2:$D$454) -> 23 | L20: =SUMIF('원본 (분리)'!$B$2:$B$454,$J20,'원본 (분리)'!$E$2:$E$454) -> 21 | M20: =IFERROR((L20/K20)*100,) -> 91.304348 | O20: 충북 | P20: 0 | Q20: 81
B21: 울산중부 | C21: 경남 | H21: =VLOOKUP(I21,$B$2:$C$64,2,0) -> 경남 | I21: 진주 | J21: 엠마우스 요양병원 | K21: =SUMIF('원본 (분리)'!$B$2:$B$454,J21,'원본 (분리)'!$D$2:$D$454) -> 21 | L21: =SUMIF('원본 (분리)'!$B$2:$B$454,$J21,'원본 (분리)'!$E$2:$E$454) -> 21 | M21: =IFERROR((L21/K21)*100,) -> 100 | O21: 총합계 | P21: 4647 | Q21: 14990
B22: 진주 | C22: 경남 | H22: =VLOOKUP(I22,$B$2:$C$64,2,0) -> 경남 | I22: 진주 | J22: 센텀병원 | K22: =SUMIF('원본 (분리)'!$B$2:$B$454,J22,'원본 (분리)'!$D$2:$D$454) -> 21 | L22: =SUMIF('원본 (분리)'!$B$2:$B$454,$J22,'원본 (분리)'!$E$2:$E$454) -> 19 | M22: =IFERROR((L22/K22)*100,) -> 90.47619
B23: 창원 | C23: 경남 | H23: =VLOOKUP(I23,$B$2:$C$64,2,0) -> 경기 | I23: 용인 | J23: 카리스요양병원 | K23: =SUMIF('원본 (분리)'!$B$2:$B$454,J23,'원본 (분리)'!$D$2:$D$454) -> 19 | L23: =SUMIF('원본 (분리)'!$B$2:$B$454,$J23,'원본 (분리)'!$E$2:$E$454) -> 19 | M23: =IFERROR((L23/K23)*100,) -> 100
B24: 통영 | C24: 경남 | H24: =VLOOKUP(I24,$B$2:$C$64,2,0) -> 경북 | I24: 대구남부 | J24: 대구기독병원 | K24: =SUMIF('원본 (분리)'!$B$2:$B$454,J24,'원본 (분리)'!$D$2:$D$454) -> 18 | L24: =SUMIF('원본 (분리)'!$B$2:$B$454,$J24,'원본 (분리)'!$E$2:$E$454) -> 16 | M24: =IFERROR((L24/K24)*100,) -> 88.888889
B25: 경주 | C25: 경북 | H25: =VLOOKUP(I25,$B$2:$C$64,2,0) -> 경북 | I25: 대구남부 | J25: 이상엽내과의원 | K25: =SUMIF('원본 (분리)'!$B$2:$B$454,J25,'원본 (분리)'!$D$2:$D$454) -> 16 | L25: =SUMIF('원본 (분리)'!$B$2:$B$454,$J25,'원본 (분리)'!$E$2:$E$454) -> 14 | M25: =IFERROR((L25/K25)*100,) -> 87.5
B26: 구미 | C26: 경북 | H26: =VLOOKUP(I26,$B$2:$C$64,2,0) -> 서울 | I26: 서울서부 | J26: 목동연세365의원 | K26: =SUMIF('원본 (분리)'!$B$2:$B$454,J26,'원본 (분리)'!$D$2:$D$454) -> 14 | L26: =SUMIF('원본 (분리)'!$B$2:$B$454,$J26,'원본 (분리)'!$E$2:$E$454) -> 14 | M26: =IFERROR((L26/K26)*100,) -> 100
B27: 김천(출) | C27: 경북 | H27: =VLOOKUP(I27,$B$2:$C$64,2,0) -> 경북 | I27: 대구남부 | J27: 범어샘편한내과 | K27: =SUMIF('원본 (분리)'!$B$2:$B$454,J27,'원본 (분리)'!$D$2:$D$454) -> 27 | L27: =SUMIF('원본 (분리)'!$B$2:$B$454,$J27,'원본 (분리)'!$E$2:$E$454) -> 13 | M27: =IFERROR((L27/K27)*100,) -> 48.148148
B28: 대구남부 | C28: 경북 | H28: =VLOOKUP(I28,$B$2:$C$64,2,0) -> 경기 | I28: 수원북부 | J28: 나누리수원병원(외주) | K28: =SUMIF('원본 (분리)'!$B$2:$B$454,J28,'원본 (분리)'!$D$2:$D$454) -> 23 | L28: =SUMIF('원본 (분리)'!$B$2:$B$454,$J28,'원본 (분리)'!$E$2:$E$454) -> 13 | M28: =IFERROR((L28/K28)*100,) -> 56.521739
B29: 대구중부 | C29: 경북 | H29: =VLOOKUP(I29,$B$2:$C$64,2,0) -> 경기 | I29: 용인 | J29: 분당21세기의원 | K29: =SUMIF('원본 (분리)'!$B$2:$B$454,J29,'원본 (분리)'!$D$2:$D$454) -> 13 | L29: =SUMIF('원본 (분리)'!$B$2:$B$454,$J29,'원본 (분리)'!$E$2:$E$454) -> 13 | M29: =IFERROR((L29/K29)*100,) -> 100
B30: 대구서부 | C30: 경북 | H30: =VLOOKUP(I30,$B$2:$C$64,2,0) -> 인천 | I30: 인천 | J30: 강문호내과 | K30: =SUMIF('원본 (분리)'!$B$2:$B$454,J30,'원본 (분리)'!$D$2:$D$454) -> 12 | L30: =SUMIF('원본 (분리)'!$B$2:$B$454,$J30,'원본 (분리)'!$E$2:$E$454) -> 12 | M30: =IFERROR((L30/K30)*100,) -> 100
B31: 상주 | C31: 경북 | H31: =VLOOKUP(I31,$B$2:$C$64,2,0) -> 서울 | I31: 용산(출) | J31: 연세중앙내과의원 | K31: =SUMIF('원본 (분리)'!$B$2:$B$454,J31,'원본 (분리)'!$D$2:$D$454) -> 15 | L31: =SUMIF('원본 (분리)'!$B$2:$B$454,$J31,'원본 (분리)'!$E$2:$E$454) -> 11 | M31: =IFERROR((L31/K31)*100,) -> 73.333333
B32: 안동 | C32: 경북 | H32: =VLOOKUP(I32,$B$2:$C$64,2,0) -> 경북 | I32: 대구남부 | J32: 용각의료재단 한신병원 | K32: =SUMIF('원본 (분리)'!$B$2:$B$454,J32,'원본 (분리)'!$D$2:$D$454) -> 14 | L32: =SUMIF('원본 (분리)'!$B$2:$B$454,$J32,'원본 (분리)'!$E$2:$E$454) -> 11 | M32: =IFERROR((L32/K32)*100,) -> 78.571429
B33: 포항 | C33: 경북 | H33: =VLOOKUP(I33,$B$2:$C$64,2,0) -> 전북 | I33: 전북 | J33: 구기선내과의원 | K33: =SUMIF('원본 (분리)'!$B$2:$B$454,J33,'원본 (분리)'!$D$2:$D$454) -> 11 | L33: =SUMIF('원본 (분리)'!$B$2:$B$454,$J33,'원본 (분리)'!$E$2:$E$454) -> 11 | M33: =IFERROR((L33/K33)*100,) -> 100
... B64: 전국 | C64: 전국 | H64: =VLOOKUP(I64,$B$2:$C$64,2,0) -> 서울 | I64: 서울남부 | J64: 아산진내과의원 | K64: =SUMIF('원본 (분리)'!$B$2:$B$454,J64,'원본 (분리)'!$D$2:$D$454) -> 4 | L64: =SUMIF('원본 (분리)'!$B$2:$B$454,$J64,'원본 (분리)'!$E$2:$E$454) -> 4 | M64: =IFERROR((L64/K64)*100,) -> 100
H65: =VLOOKUP(I65,$B$2:$C$64,2,0) -> 서울 | I65: 서울동부 | J65: 주용진내과의원 | K65: =SUMIF('원본 (분리)'!$B$2:$B$454,J65,'원본 (분리)'!$D$2:$D$454) -> 4 | L65: =SUMIF('원본 (분리)'!$B$2:$B$454,$J65,'원본 (분리)'!$E$2:$E$454) -> 4 | M65: =IFERROR((L65/K65)*100,) -> 100
H66: =VLOOKUP(I66,$B$2:$C$64,2,0) -> 경기 | I66: 수원북부 | J66: 한빛현요양병원 | K66: =SUMIF('원본 (분리)'!$B$2:$B$454,J66,'원본 (분리)'!$D$2:$D$454) -> 4 | L66: =SUMIF('원본 (분리)'!$B$2:$B$454,$J66,'원본 (분리)'!$E$2:$E$454) -> 4 | M66: =IFERROR((L66/K66)*100,) -> 100
H67: =VLOOKUP(I67,$B$2:$C$64,2,0) -> 경기 | I67: 일산 | J67: 일산호수 요양병원 | K67: =SUMIF('원본 (분리)'!$B$2:$B$454,J67,'원본 (분리)'!$D$2:$D$454) -> 4 | L67: =SUMIF('원본 (분리)'!$B$2:$B$454,$J67,'원본 (분리)'!$E$2:$E$454) -> 4 | M67: =IFERROR((L67/K67)*100,) -> 100
H68: =VLOOKUP(I68,$B$2:$C$64,2,0) -> 전남 | I68: 호남 | J68: 화순중앙병원 | K68: =SUMIF('원본 (분리)'!$B$2:$B$454,J68,'원본 (분리)'!$D$2:$D$454) -> 4 | L68: =SUMIF('원본 (분리)'!$B$2:$B$454,$J68,'원본 (분리)'!$E$2:$E$454) -> 4 | M68: =IFERROR((L68/K68)*100,) -> 100
H69: =VLOOKUP(I69,$B$2:$C$64,2,0) -> 충남 | I69: 홍성 | J69: 열린의원(보령) | K69: =SUMIF('원본 (분리)'!$B$2:$B$454,J69,'원본 (분리)'!$D$2:$D$454) -> 4 | L69: =SUMIF('원본 (분리)'!$B$2:$B$454,$J69,'원본 (분리)'!$E$2:$E$454) -> 4 | M69: =IFERROR((L69/K69)*100,) -> 100
H70: =VLOOKUP(I70,$B$2:$C$64,2,0) -> 경북 | I70: 안동 | J70: (재)안동성소병원유지재단 | K70: =SUMIF('원본 (분리)'!$B$2:$B$454,J70,'원본 (분리)'!$D$2:$D$454) -> 194 | L70: =SUMIF('원본 (분리)'!$B$2:$B$454,$J70,'원본 (분리)'!$E$2:$E$454) -> 3 | M70: =IFERROR((L70/K70)*100,) -> 1.5463918
H71: =VLOOKUP(I71,$B$2:$C$64,2,0) -> 경북 | I71: 대구남부 | J71: 한성재단동아메디병원 | K71: =SUMIF('원본 (분리)'!$B$2:$B$454,J71,'원본 (분리)'!$D$2:$D$454) -> 36 | L71: =SUMIF('원본 (분리)'!$B$2:$B$454,$J71,'원본 (분리)'!$E$2:$E$454) -> 3 | M71: =IFERROR((L71/K71)*100,) -> 8.3333333
...

Sheet 원본 (분리)
A1: 특정검사 리마크, 코멘트 병원별 건수 | E1: 부적합 | F1: 적합
A2: 영업소명 | B2: 병원명 | C2: 검사명 | D2: 접수건수 | E2: 코멘트 입력 건수 | F2: 코멘트 미입력 건수 | G2: 리마크 입력 건수 | H2: 리마크 미입력 건수 | J2: 중복된 항목제거(병원명기준)
A3: 강릉 | B3: 근로복지공단 동해병원 | C3: ACTH | D3: 20 | E3: 0 | F3: 20 | J3: 강릉 | K3: 근로복지공단 동해병원
A4: 강릉 | B4: 윤내과의원 | C4: ACTH | D4: 1 | E4: 0 | F4: 1 | J4: 강릉 | K4: 윤내과의원
A5: 경주 | B5: 굿모닝병원 | C5: ACTH | D5: 25 | E5: 0 | F5: 25 | J5: 경주 | K5: 굿모닝병원
A6: 경주 | B6: 늘속편한내과 | C6: ACTH | D6: 1 | E6: 1 | F6: 0 | J6: 경주 | K6: 늘속편한내과
A7: 경주 | B7: 바른몸의원 | C7: ACTH | D7: 711 | E7: 703 | F7: 8 | J7: 경주 | K7: 바른몸의원
A8: 경주 | B8: 새천년병원 | C8: ACTH | D8: 19 | E8: 0 | F8: 19 | J8: 경주 | K8: 새천년병원
A9: 경주 | B9: 안강아산내과의원 | C9: ACTH | D9: 1 | E9: 0 | F9: 1 | J9: 경주 | K9: 안강아산내과의원
A10: 광명(출) | B10: 광명21세기병원 | C10: ACTH | D10: 1 | E10: 0 | F10: 1 | J10: 광명(출) | K10: 광명21세기병원
A11: 광명(출) | B11: 의료법인희명의료재단 | C11: ACTH | D11: 54 | E11: 0 | F11: 54 | J11: 광명(출) | K11: 의료법인희명의료재단
A12: 광명(출) | B12: 중앙대학교광명병원 | C12: ACTH | D12: 187 | E12: 0 | F12: 187 | J12: 광명(출) | K12: 중앙대학교광명병원
A13: 광주 | B13: 광주기독병원 | C13: ACTH | D13: 303 | E13: 0 | F13: 303 | J13: 광주 | K13: 광주365재활병원
A14: 광주 | B14: 광주보훈병원 | C14: ACTH | D14: 215 | E14: 4 | F14: 211 | J14: 광주 | K14: 광주기독병원
... A398: 순천 | B398: 메디팜요양병원 | C398: Ammonia | D398: 3 | E398: 0 | F398: 3 | J398: QM팀 | K398: KAEQAS 국내정도관리
A399: 순천 | B399: 순천하나병원 | C399: Ammonia | D399: 1 | E399: 0 | F399: 1
A400: 순천 | B400: (의)동인요양병원 | C400: Ammonia | D400: 6 | E400: 0 | F400: 6
A401: 안동 | B401: (의)영제의료재단 | C401: Ammonia | D401: 3 | E401: 3 | F401: 0
A402: 안산 | B402: 경기도립노인전문시흥병원 | C402: Ammonia | D402: 3 | E402: 0 | F402: 3
A403: 안산 | B403: 미라클요양병원 | C403: Ammonia | D403: 2 | E403: 2 | F403: 0
A404: 양평(출) | B404: 한길의원 | C404: Ammonia | D404: 1 | E404: 1 | F404: 0
A405: 영서2 | B405: 현대요양병원 | C405: Ammonia | D405: 50 | E405: 0 | F405: 50
A406: 용산(출) | B406: 송도병원 | C406: Ammonia | D406: 1 | E406: 0 | F406: 1
A407: 용인 | B407: 카리스요양병원 | C407: Ammonia | D407: 19 | E407: 19 | F407: 0
A408: 용인 | B408: (의)용인병원유지재단 | C408: Ammonia | D408: 1 | E408: 0 | F408: 1
A409: 울산중부 | B409: 울산엘리야병원 | C409: Ammonia | D409: 5 | E409: 5 | F409: 0
A410: 원주 | B410: 연세준내과 | C410: Ammonia | D410: 6 | E410: 1 | F410: 5
... A454: 홍성 | B454: [당진]민의원 | C454: Ammonia | D454: 1 | E454: 1 | F454: 0

Sheet 1.원본
A1: 특정검사 리마크, 코멘트 병원별 건수
A2: 영업소명 | B2: 병원명 | C2: 검사명 | D2: 접수건수 | E2: 코멘트 입력 건수 | F2: 코멘트 미입력 건수 | G2: 리마크 입력 건수 | H2: 리마크 미입력 건수 | K2: ⓐ접수월 선택 -> ⓑ전체복사/붙여넣기 -> ⓑ검사명-Ammonia 데이터 삭제하기 -> A~F 열까지 복사하여 2. 거래내역에 붙여넣기
A3: 오창 | B3: 키우리소아청소년과의원 | C3: ACTH | D3: 276 | E3: 275 | F3: 1 | G3: 0 | H3: 0
A4: 서울서부 | B4: 바른키움소아청소년과의원 | C4: ACTH | D4: 137 | E4: 137 | F4: 0 | G4: 0 | H4: 0
A5: 경주 | B5: 바른몸의원 | C5: ACTH | D5: 114 | E5: 114 | F5: 0 | G5: 0 | H5: 0
A6: 인천 | B6: 인천터미널 정형외과의원 | C6: ACTH | D6: 97 | E6: 97 | F6: 0 | G6: 0 | H6: 0
A7: 울산중부 | B7: 울산병원 | C7: ACTH | D7: 89 | E7: 88 | F7: 1 | G7: 0 | H7: 0
A8: 원주 | B8: 명지병원(제천) | C8: ACTH | D8: 41 | E8: 39 | F8: 2 | G8: 0 | H8: 0
A9: 서울강남 | B9: 신사터미널마취통증의학과 | C9: ACTH | D9: 35 | E9: 35 | F9: 0 | G9: 0 | H9: 0
A10: 서울중부 | B10: 서울케이(K)내과의원 | C10: ACTH | D10: 32 | E10: 27 | F10: 5 | G10: 0 | H10: 0
A11: 대구남부 | B11: 청춘내과의원 | C11: ACTH | D11: 46 | E11: 18 | F11: 28 | G11: 0 | H11: 0
A12: 전북 | B12: 박은재 내과 | C12: ACTH | D12: 6 | E12: 6 | F12: 0 | G12: 0 | H12: 0
A13: 김포 | B13: (의)성세의료재단뉴성민병원 | C13: ACTH | D13: 7 | E13: 5 | F13: 2 | G13: 0 | H13: 0
A14: 서울강남 | B14: 트리니티여성의원 | C14: ACTH | D14: 11 | E14: 3 | F14: 8 | G14: 0 | H14: 0
... A226: 경주 | B226: 굿모닝병원 | C226: Ammonia | D226: 63 | E226: 63 | F226: 0 | G226: 63 | H226: 0

Sheet Sheet3
B3: 열 레이블
B4: 2023년03월 | D4: 2023년02월 | F4: 2023년01월 | K4: =B4 -> 2023년03월 | M4: =D4 -> 2023년02월 | O4: =F4 -> 2023년01월
A5: 행 레이블 | B5: 합계 : 접수건수 | C5: 합계 : 코멘트 입력 건수 | D5: 합계 : 접수건수 | E5: 합계 : 코멘트 입력 건수 | F5: 합계 : 접수건수 | G5: 합계 : 코멘트 입력 건수 | J5: 구분 | K5: 총 건수 | L5: 부적합 | M5: 총 건수 | N5: 부적합 | O5: 총 건수 | P5: 부적합 | Q5: 3월 | R5: 2월 | S5: 1월
A6: (SHC)연세대학교 의과대학 | B6: 152 | C6: 0 | D6: 68 | E6: 0 | J6: 키우리소아청소년과의원 | K6: 276 | L6: 275 | M6: 283 | N6: 282 | O6: 305 | P6: 303 | Q6: =L6/K6 -> 0.99637681 | R6: =N6/M6 -> 0.99646643 | S6: =P6/O6 -> 0.99344262
A7: (사)삼동회 정읍시립요양병원 | B7: 1 | C7: 1 | J7: 바른키움소아청소년과의원 | K7: 137 | L7: 137 | M7: 105 | N7: 105 | O7: 95 | P7: 91 | Q7: =L7/K7 -> 1 | R7: =N7/M7 -> 1 | S7: =P7/O7 -> 0.95789474
A8: (의)대명의료재단 서대구병원 | B8: 4 | C8: 1 | D8: 1 | E8: 0 | F8: 2 | G8: 0 | J8: 바른몸의원 | K8: 114 | L8: 114 | M8: 172 | N8: 172 | O8: 136 | P8: 134 | Q8: =L8/K8 -> 1 | R8: =N8/M8 -> 1 | S8: =P8/O8 -> 0.98529412
A9: (의)보강병원 | B9: 4 | C9: 0 | D9: 4 | E9: 0 | J9: 인천터미널 정형외과의원 | K9: 97 | L9: 97 | M9: 99 | N9: 98 | O9: 113 | P9: 111 | Q9: =L9/K9 -> 1 | R9: =N9/M9 -> 0.98989899 | S9: =P9/O9 -> 0.98230088
A10: (의)삼백의료재단상주성모병원 | D10: 3 | E10: 0 | F10: 4 | G10: 0 | J10: 울산병원 | K10: 89 | L10: 88 | M10: 73 | N10: 73 | O10: 59 | P10: 57 | Q10: =L10/K10 -> 0.98876404 | R10: =N10/M10 -> 1 | S10: =P10/O10 -> 0.96610169
A11: (의)상주적십자병원 | D11: 1 | E11: 0 | J11: 굿모닝병원 | K11: 65 | L11: 63 | M11: 4 | N11: 0 | O11: 7 | P11: 0 | Q11: =L11/K11 -> 0.96923077 | R11: =N11/M11 -> 0 | S11: =P11/O11 -> 0
A12: (의)성세의료재단뉴성민병원 | B12: 7 | C12: 5 | D12: 1 | E12: 1 | J12: 명지병원(제천) | K12: 41 | L12: 39 | M12: 13 | N12: 10 | O12: 21 | P12: 18 | Q12: =L12/K12 -> 0.95121951 | R12: =N12/M12 -> 0.76923077 | S12: =P12/O12 -> 0.85714286
A13: (의)안동병원 | B13: 146 | C13: 0 | D13: 124 | E13: 0 | F13: 130 | G13: 0 | J13: 신사터미널마취통증의학과 | K13: 35 | L13: 35 | M13: 5 | N13: 5 | Q13: =L13/K13 -> 1 | R13: =N13/M13 -> 1 | S13: =P13/O13 -> #DIV/0!
A14: (의)영훈의료재단대전선병원 | B14: 29 | C14: 0 | D14: 30 | E14: 0 | F14: 25 | G14: 0 | J14: 서울케이(K)내과의원 | K14: 32 | L14: 27 | M14: 27 | N14: 25 | O14: 32 | P14: 25 | Q14: =L14/K14 -> 0.84375 | R14: =N14/M14 -> 0.92592593 | S14: =P14/O14 -> 0.78125
A15: (의)영훈의료재단유성선병원 | B15: 67 | C15: 0 | D15: 51 | E15: 0 | F15: 58 | G15: 0 | J15: 한빛병원 | K15: 27 | L15: 27 | M15: 1 | N15: 1 | Q15: =L15/K15 -> 1 | R15: =N15/M15 -> 1 | S15: =P15/O15 -> #DIV/0!
A16: (의)한성재단포항세명기독병원 | B16: 79 | C16: 0 | D16: 63 | E16: 0 | F16: 66 | G16: 0 | J16: 청춘내과의원 | K16: 46 | L16: 18 | M16: 27 | N16: 17 | O16: 42 | P16: 19 | Q16: =L16/K16 -> 0.39130435 | R16: =N16/M16 -> 0.62962963 | S16: =P16/O16 -> 0.45238095
A17: (의료)문성의료재단 | B17: 7 | C17: 0 | J17: 우리내과의원 | K17: 28 | L17: 4 | M17: 27 | N17: 5 | O17: 21 | P17: 3 | Q17: =L17/K17 -> 0.14285714 | R17: =N17/M17 -> 0.18518519 | S17: =P17/O17 -> 0.14285714
A18: (재)강남하나로 | F18: 1 | G18: 0 | J18: 트리니티여성의원 | K18: 11 | L18: 3 | M18: 5 | N18: 5 | O18: 6 | P18: 6 | Q18: =L18/K18 -> 0.27272727 | R18: =N18/M18 -> 1 | S18: =P18/O18 -> 1
A19: (재)안동성소병원유지재단 | B19: 19 | C19: 0 | D19: 44 | E19: 0 | F19: 38 | G19: 2 | J19: SAM CHEON PO JEIL HOSPITAL | K19: 16 | L19: 2 | M19: 14 | N19: 6 | O19: 34 | P19: 5 | Q19: =L19/K19 -> 0.125 | R19: =N19/M19 -> 0.42857143 | S19: =P19/O19 -> 0.14705882
A20: 21세기병원(원주) | D20: 1 | E20: 1 | J20: 박은재 내과 | K20: 6 | L20: 6 | M20: 5 | N20: 5 | O20: 2 | P20: 1 | Q20: =L20/K20 -> 1 | R20: =N20/M20 -> 1 | S20: =P20/O20 -> 0.5
A21: CAP 국외정도관리 | B21: 5 | C21: 5 | F21: 3 | G21: 0 | J21: (의)성세의료재단뉴성민병원 | K21: 7 | L21: 5 | M21: 1 | N21: 1 | Q21: =L21/K21 -> 0.71428571 | R21: =N21/M21 -> 1 | S21: =P21/O21 -> #DIV/0!
A22: JINJU BOKUM HOSPITAL | B22: 28 | C22: 0 | D22: 14 | E22: 0 | F22: 20 | G22: 0 | J22: CAP 국외정도관리 | K22: 5 | L22: 5 | O22: 3 | P22: 0 | Q22: =L22/K22 -> 1 | R22: =N22/M22 -> #DIV/0! | S22: =P22/O22 -> 0
A23: NAM HAE HOSPITAL | B23: 7 | C23: 0 | D23: 6 | E23: 0 | F23: 9 | G23: 0 | J23: 의료법인 강혜의료재단 | K23: 5 | L23: 5 | Q23: =L23/K23 -> 1 | R23: =N23/M23 -> #DIV/0! | S23: =P23/O23 -> #DIV/0!
A24: SAM CHEON PO JEIL HOSPITAL | B24: 16 | C24: 2 | D24: 14 | E24: 6 | F24: 34 | G24: 5 | J24: 이현진신경과&김은정내과의원 | K24: 5 | L24: 5
A25: WONJIN GREEN HOSPITAL | D25: 1 | E25: 0 | F25: 2 | G25: 0 | J25: 효사랑전주요양병원 | K25: 4 | L25: 4
A26: W진 병원(부천) | B26: 3 | C26: 2 | J26: 정읍한국병원 | K26: 7 | L26: 3 | M26: 5 | N26: 0 | O26: 7 | P26: 3
A27: YONSEI S HOSPITAL | B27: 3 | C27: 0 | D27: 2 | E27: 0 | F27: 2 | G27: 0 | J27: 효사랑가족요양병원 | K27: 5 | L27: 3
A28: 강남나누리병원 | B28: 12 | C28: 0 | D28: 10 | E28: 0 | F28: 18 | G28: 0 | J28: 센텀병원 | K28: 3 | L28: 3
A29: 강남병원 | B29: 2 | C29: 0 | J29: 유앤이내과 | K29: 29 | L29: 2 | M29: 16 | N29: 0 | O29: 25 | P29: 0
A30: 강문호내과 | B30: 2 | C30: 2 | D30: 4 | E30: 4 | F30: 2 | G30: 2 | J30: 용각의료재단 한신병원 | K30: 22 | L30: 2
A31: 강미정연합내과의원 | F31: 1 | G31: 0 | J31: 대구기독병원 | K31: 8 | L31: 2 | M31: 1 | N31: 0 | O31: 1 | P31: 0
A32: 강북연세병원 | B32: 4 | C32: 0 | J32: 의)나누리의료재단 | K32: 5 | L32: 2 | M32: 7 | N32: 0 | O32: 4 | P32: 0
A33: 건강한내과 | D33: 1 | E33: 0 | J33: 성서병원 | K33: 4 | L33: 2
A34: 건국대학교충주병원 | B34: 12 | C34: 0 | D34: 9 | E34: 1 | F34: 10 | G34: 0 | J34: 원대연합의원 | K34: 3 | L34: 2 | M34: 2 | N34: 1
A35: 경빈의료재단 김해센텀병원 | B35: 5 | C35: 0 | D35: 2 | E35: 0 | J35: W진 병원(부천) | K35: 3 | L35: 2
A36: 경상북도김천의료원 | B36: 14 | C36: 0 | D36: 9 | E36: 0 | F36: 25 | G36: 0 | J36: 이상엽내과의원 | K36: 2 | L36: 2 | M36: 4 | N36: 4 | O36: 4 | P36: 4
A37: 경상북도안동의료원(임상) | F37: 1 | G37: 1 | J37: 강문호내과 | K37: 2 | L37: 2 | M37: 4 | N37: 4 | O37: 2 | P37: 2
A38: 경찰병원 | B38: 31 | C38: 0 | D38: 26 | E38: 0 | F38: 18 | G38: 0 | J38: 좋은내과 | K38: 2 | L38: 2 | M38: 2 | N38: 2 | O38: 3 | P38: 3
A39: 경희늘푸른노인전문병원 | B39: 1 | C39: 0 | J39: 분당21세기의원 | K39: 2 | L39: 2 | M39: 1 | N39: 1 | O39: 1 | P39: 1
A40: 광주굿모닝병원 | B40: 1 | C40: 0 | J40: 서송병원 | K40: 2 | L40: 2 | M40: 1 | N40: 0 | O40: 4 | P40: 2
A41: 광주기독병원 | B41: 57 | C41: 1 | D41: 48 | E41: 0 | F41: 43 | G41: 0 | J41: 광주소망병원 | K41: 2 | L41: 2 | M41: 1 | N41: 0 | O41: 1 | P41: 0
A42: 광주보훈병원 | B42: 58 | C42: 0 | D42: 56 | E42: 0 | F42: 47 | G42: 0 | J42: 바른척척의원 | K42: 2 | L42: 2 | O42: 1 | P42: 1
...

Sheet 2.거래내역
E7: 조회기간 | K7: 데이터 붙여넣기
E8: 총건수 | F8: =SUM(접수건수) -> 37864 | K8: 서식 붙여넣기
E9: 부적합건수 | F9: =SUM(부적합건수) -> 10728 | K9: 데이터 입력
B11: 접수년 | C11: 접수월 | D11: 접수년월 | E11: 지역명 | F11: 영업소명 | G11: 병원명 | H11: 검사명 | I11: 접수건수 | J11: 코멘트 입력 건수 | K11: 코멘트 미입력 건수 | N11: 영업소명 | O11: 지역별
B12: 2022년 | C12: 01월 | D12: =B12&C12 -> 2022년01월 | E12: =VLOOKUP($F12,$N$11:$O$78,2,0) -> 영동 | F12: 강릉 | G12: 근로복지공단 동해병원 | H12: ACTH | I12: 2 | J12: 0 | K12: 2 | N12: 김포 | O12: 경기
B13: 2022년 | C13: 01월 | D13: =B13&C13 -> 2022년01월 | E13: =VLOOKUP($F13,$N$11:$O$78,2,0) -> 경북 | F13: 경주 | G13: 굿모닝병원 | H13: ACTH | I13: 1 | J13: 0 | K13: 1 | N13: 부천 | O13: 경기
B14: 2022년 | C14: 01월 | D14: =B14&C14 -> 2022년01월 | E14: =VLOOKUP($F14,$N$11:$O$78,2,0) -> 경북 | F14: 경주 | G14: 바른몸의원 | H14: ACTH | I14: 116 | J14: 116 | K14: 0 | N14: 성남(출) | O14: 경기
B15: 2022년 | C15: 01월 | D15: =B15&C15 -> 2022년01월 | E15: =VLOOKUP($F15,$N$11:$O$78,2,0) -> 서울 | F15: 광명(출) | G15: 광명21세기병원 | H15: ACTH | I15: 1 | J15: 0 | K15: 1 | N15: 수원남부 | O15: 경기
B16: 2022년 | C16: 01월 | D16: =B16&C16 -> 2022년01월 | E16: =VLOOKUP($F16,$N$11:$O$78,2,0) -> 서울 | F16: 광명(출) | G16: 의료법인희명의료재단 | H16: ACTH | I16: 3 | J16: 0 | K16: 3 | N16: 수원북부 | O16: 경기
B17: 2022년 | C17: 01월 | D17: =B17&C17 -> 2022년01월 | E17: =VLOOKUP($F17,$N$11:$O$78,2,0) -> 전남 | F17: 광주 | G17: 광주기독병원 | H17: ACTH | I17: 47 | J17: 0 | K17: 47 | N17: 안산 | O17: 경기
B18: 2022년 | C18: 01월 | D18: =B18&C18 -> 2022년01월 | E18: =VLOOKUP($F18,$N$11:$O$78,2,0) -> 전남 | F18: 광주 | G18: 광주보훈병원 | H18: ACTH | I18: 46 | J18: 0 | K18: 46 | N18: 양평(출) | O18: 경기
B19: 2022년 | C19: 01월 | D19: =B19&C19 -> 2022년01월 | E19: =VLOOKUP($F19,$N$11:$O$78,2,0) -> 전남 | F19: 광주 | G19: 광주수완병원 | H19: ACTH | I19: 2 | J19: 0 | K19: 2 | N19: 일산 | O19: 경기
B20: 2022년 | C20: 01월 | D20: =B20&C20 -> 2022년01월 | E20: =VLOOKUP($F20,$N$11:$O$78,2,0) -> 전남 | F20: 광주 | G20: 광주현대병원 | H20: ACTH | I20: 9 | J20: 0 | K20: 9 | N20: 파주(출) | O20: 경기
B21: 2022년 | C21: 01월 | D21: =B21&C21 -> 2022년01월 | E21: =VLOOKUP($F21,$N$11:$O$78,2,0) -> 전남 | F21: 광주 | G21: 미래로21병원 | H21: ACTH | I21: 13 | J21: 0 | K21: 13 | N21: 평택 | O21: 경기
B22: 2022년 | C22: 01월 | D22: =B22&C22 -> 2022년01월 | E22: =VLOOKUP($F22,$N$11:$O$78,2,0) -> 전남 | F22: 광주 | G22: 바른몸의원 | H22: ACTH | I22: 1 | J22: 1 | K22: 0 | N22: 용인 | O22: 경기
B23: 2022년 | C23: 01월 | D23: =B23&C23 -> 2022년01월 | E23: =VLOOKUP($F23,$N$11:$O$78,2,0) -> 전남 | F23: 광주 | G23: 신가병원 | H23: ACTH | I23: 1 | J23: 0 | K23: 1 | N23: 김해 | O23: 경남
... B78: 2022년 | C78: 01월 | D78: =B78&C78 -> 2022년01월 | E78: =VLOOKUP($F78,$N$11:$O$78,2,0) -> 서울 | F78: 서울서부 | G78: 동신종합병원 | H78: ACTH | I78: 23 | J78: 0 | K78: 23 | N78: 검사운영지원팀 | O78: 본원
B79: 2022년 | C79: 01월 | D79: =B79&C79 -> 2022년01월 | E79: =VLOOKUP($F79,$N$11:$O$78,2,0) -> 서울 | F79: 서울서부 | G79: 목동연세365의원 | H79: ACTH | I79: 4 | J79: 4 | K79: 0
B80: 2022년 | C80: 01월 | D80: =B80&C80 -> 2022년01월 | E80: =VLOOKUP($F80,$N$11:$O$78,2,0) -> 서울 | F80: 서울중부 | G80: 서울케이(K)내과의원 | H80: ACTH | I80: 41 | J80: 26 | K80: 15
B81: 2022년 | C81: 01월 | D81: =B81&C81 -> 2022년01월 | E81: =VLOOKUP($F81,$N$11:$O$78,2,0) -> 서울 | F81: 서울중부 | G81: 송도병원 | H81: ACTH | I81: 1 | J81: 0 | K81: 1
B82: 2022년 | C82: 01월 | D82: =B82&C82 -> 2022년01월 | E82: =VLOOKUP($F82,$N$11:$O$78,2,0) -> 서울 | F82: 서울중부 | G82: 의료법인 소화병원 | H82: ACTH | I82: 35 | J82: 16 | K82: 19
B83: 2022년 | C83: 01월 | D83: =B83&C83 -> 2022년01월 | E83: =VLOOKUP($F83,$N$11:$O$78,2,0) -> 충남 | F83: 세종(출) | G83: 유앤이내과 | H83: ACTH | I83: 39 | J83: 0 | K83: 39
B84: 2022년 | C84: 01월 | D84: =B84&C84 -> 2022년01월 | E84: =VLOOKUP($F84,$N$11:$O$78,2,0) -> 서울 | F84: 송파 | G84: 경찰병원 | H84: ACTH | I84: 20 | J84: 0 | K84: 20
B85: 2022년 | C85: 01월 | D85: =B85&C85 -> 2022년01월 | E85: =VLOOKUP($F85,$N$11:$O$78,2,0) -> 경기 | F85: 수원남부 | G85: 베데스다병원 | H85: ACTH | I85: 1 | J85: 0 | K85: 1
B86: 2022년 | C86: 01월 | D86: =B86&C86 -> 2022년01월 | E86: =VLOOKUP($F86,$N$11:$O$78,2,0) -> 전남 | F86: 순천 | G86: 순천하나병원 | H86: ACTH | I86: 13 | J86: 0 | K86: 13
B87: 2022년 | C87: 01월 | D87: =B87&C87 -> 2022년01월 | E87: =VLOOKUP($F87,$N$11:$O$78,2,0) -> 전남 | F87: 순천 | G87: 여수한국병원 | H87: ACTH | I87: 21 | J87: 0 | K87: 21
B88: 2022년 | C88: 01월 | D88: =B88&C88 -> 2022년01월 | E88: =VLOOKUP($F88,$N$11:$O$78,2,0) -> 전남 | F88: 순천 | G88: 틔움가정의학과 | H88: ACTH | I88: 1 | J88: 0 | K88: 1
B89: 2022년 | C89: 01월 | D89: =B89&C89 -> 2022년01월 | E89: =VLOOKUP($F89,$N$11:$O$78,2,0) -> 전남 | F89: 순천 | G89: (의)좌수영의료재단 | H89: ACTH | I89: 1 | J89: 0 | K89: 1
B90: 2022년 | C90: 01월 | D90: =B90&C90 -> 2022년01월 | E90: =VLOOKUP($F90,$N$11:$O$78,2,0) -> 경북 | F90: 안동 | G90: (의)안동병원 | H90: ACTH | I90: 78 | J90: 1 | K90: 77
... B2400: 2023년 | C2400: 03월 | D2400: =B2400&C2400 -> 2023년03월 | E2400: =VLOOKUP($F2400,$N$11:$O$78,2,0) -> 경북 | F2400: 경주 | G2400: 굿모닝병원 | H2400: Ammonia | I2400: 63 | J2400: 63 | K2400: 0

Sheet 3.피봇
B2: 부적합수(지역별) | E2: 부적합수(영업소별) | K2: 월별 현황 | Q2: 부적합수(영업소별) | X2: 월별 현황(ACTH) | AC2: 월별 현황(Ammonia)
B3: 접수평균 | C3: =IFERROR(AVERAGE(OFFSET($C$6,,,COUNTA($C$6:$C$32))),0) -> 19 | E3: 부적합평균 | F3: =IFERROR(AVERAGE(OFFSET($F$6,,,COUNTA($F$6:$F$152))),0) -> 6.3333333 | L3: 접수평균 | M3: =IFERROR(AVERAGE(OFFSET($L$6,,,COUNTA($L$6:$L$32))),0) -> 34 | N3: 총건수 | O3: =IFERROR(SUM(OFFSET($L$6,,,COUNTA($L$6:$L$32))),0) -> 34 | W3: 접수평균 | X3: ACTH | Y3: =AVERAGEIF($W$6:$W$31,$X$3,$Y$6:$Y$41) -> 34 | AB3: 접수평균 | AC3: ACTH | AD3: =AVERAGEIF($AB$6:$AB$31,$AC$3,$AD$6:$AD$41) -> #DIV/0!
L4: 부적합평균 | M4: =IFERROR(AVERAGE(OFFSET($M$6,,,COUNTA($M$6:$M$32))),0) -> 19 | N4: 부적합 | O4: =IFERROR(SUM(OFFSET($M$6,,,COUNTA($M$6:$M$32))),0) -> 19 | W4: 부적합평균 | X4: ACTH | Y4: =AVERAGEIF($W$6:$W$31,$X$3,$Z$6:$Z$41) -> 19 | AB4: 부적합평균 | AC4: ACTH | AD4: =AVERAGEIF($AB$6:$AB$31,$AC$3,$AE$6:$AE$41) -> #DIV/0!
B5: 행 레이블 | C5: 합계 : 코멘트 입력 건수 | E5: 행 레이블 | F5: 합계 : 코멘트 입력 건수 | H5: 상위 영업소 | K5: 행 레이블 | L5: 총건수 | M5: 부적합 건수 | Q5: 행 레이블 | R5: 합계 : 코멘트 입력 건수 | T5: 병원명 | U5: 건수 | W5: 검사명 | X5: 접수년월 | Y5: 합계 : 접수건수 | Z5: 합계 : 코멘트 입력 건수 | AB5: 합계 : 코멘트 미입력 건수 | AC5: 접수년월
B6: 영서 | C6: 19 | E6: 원주 | F6: 18 | H6: =E6 -> 원주 | I6: =F6 -> 18 | K6: 2023년01월 | L6: 34 | M6: 19 | Q6: 명지병원(제천) | R6: 18 | T6: =IFERROR(Q6,"") -> 명지병원(제천) | U6: =R6 -> 18 | W6: ACTH | X6: 2023년01월 | Y6: 34 | Z6: 19 | AB6: 병원명 | AC6: 2023년01월
E7: 춘천 | F7: 1 | H7: =E7 -> 춘천 | I7: =F7 -> 1 | Q7: 이봉휘내과의원 | R7: 1 | T7: =Q7 -> 이봉휘내과의원 | U7: =R7 -> 1 | AB7: 건국대학교충주병원 | AC7: 10
E8: 영서2 | F8: 0 | H8: =E8 -> 영서2 | I8: =F8 -> 0 | Q8: 건국대학교충주병원 | R8: 0 | T8: =Q8 -> 건국대학교충주병원 | U8: =R8 -> 0 | AB8: 명지병원(제천) | AC8: 3
H9: =E9 -> 0 | I9: =F9 -> 0 | Q9: 원주의료원 | R9: 0 | T9: =Q9 -> 원주의료원 | U9: =R9 -> 0 | AB9: 원주의료원 | AC9: 2
H10: =E10 -> 0 | I10: =F10 -> 0 | Q10: 총합계 | R10: 19 | T10: =Q10 -> 총합계 | U10: =R10 -> 19 | AB10: 이봉휘내과의원 | AC10: 0
H11: =E11 -> 0 | I11: =F11 -> 0 | T11: =Q11 -> 0 | U11: =R11 -> 0
H12: =E12 -> 0 | I12: =F12 -> 0 | T12: =Q12 -> 0 | U12: =R12 -> 0
H13: =E13 -> 0 | I13: =F13 -> 0 | T13: =Q13 -> 0 | U13: =R13 -> 0
H14: =E14 -> 0 | I14: =F14 -> 0 | T14: =Q14 -> 0 | U14: =R14 -> 0
H15: =E15 -> 0 | I15: =F15 -> 0 | T15: =Q15 -> 0 | U15: =R15 -> 0
T16: =Q16 -> 0 | U16: =R16 -> 0
T17: =Q17 -> 0 | U17: =R17 -> 0
T18: =Q18 -> 0 | U18: =R18 -> 0
T19: =Q19 -> 0 | U19: =R19 -> 0
T20: =Q20 -> 0 | U20: =R20 -> 0
T21: =Q21 -> 0 | U21: =R21 -> 0

Sheet 4.영업소별
B2: ⓐ접수월 선택 -> ⓑ피벗 새로고침 -> ⓑ전체 복사 -> ⓒ표에 붙여넣기 -> ⓒ전체건수 내림차순 정렬, 부적합건수 내림차순 정렬 -> 필터 부적합 0건 제외 -> 출력
A4: ⓐ | I4: 영업소별 부적합률(2023년 03월 ~ 2023년 03월)
A6: ⓑ | B6: 지역명 | C6: 영업소명 | D6: 병원명 | E6: 합계 : 접수건수 | F6: 합계 : 코멘트 입력 건수 | H6: ⓒ | I6: 지역 | J6: 영업소명 | K6: 병원명 | L6: 전체건수 | M6: 부적합건수 | N6: 비율(%) | P6: 거래처코드 | Q6: 담당자 | S6: 출처 | T6: 내용
B7: 충남 | C7: 대전 | D7: 대전보훈병원 | E7: 10 | F7: 1 | I7: 충남 | J7: 오창 | K7: 키우리소아청소년과의원 | L7: 276 | M7: 275 | N7: =IFERROR((M7/L7)*100,) -> 99.637681 | P7: 36752 | Q7: 윤창원 | S7: 기타내용 | T7: ACTH : Plasma분리후 냉동으로 보내드려야하나 여건이 되지 않아 EDTA W/B로 해주세요.
B8: 충남 | C8: 대전 | D8: (의)영훈의료재단대전선병원 | E8: 25 | F8: 0 | I8: 서울 | J8: 서울서부 | K8: 바른키움소아청소년과의원 | L8: 137 | M8: 137 | N8: =IFERROR((M8/L8)*100,) -> 100 | P8: 18673 | Q8: 선창우 | S8: 기타내용 | T8: EDTA whole blood 올립니다. /ACTH를 EDTA로 올립니다.
B9: 충남 | C9: 대전 | D9: (의)영훈의료재단유성선병원 | E9: 58 | F9: 0 | I9: 경북 | J9: 경주 | K9: 바른몸의원 | L9: 114 | M9: 114 | N9: =IFERROR((M9/L9)*100,) -> 100 | P9: 39057 | Q9: 신해솔 | S9: 기타내용 | T9: ACTH 검체 EDTA로 보냈습니다.
B10: 충남 | C10: 대전 | D10: 대전엔도내과의원 | E10: 8 | F10: 0 | I10: 인천 | J10: 인천 | K10: 인천터미널 정형외과의원 | L10: 97 | M10: 97 | N10: =IFERROR((M10/L10)*100,) -> 100 | P10: 32359 | Q10: 유영춘 | S10: 설문내용 | T10: 업무량이 많다는 이유로 검체 분리를 실시하지 않음
B11: 충남 | C11: 대전 | D11: 반석편한신경외과 | E11: 5 | F11: 0 | I11: 경남 | J11: 울산중부 | K11: 울산병원 | L11: 89 | M11: 88 | N11: =IFERROR((M11/L11)*100,) -> 98.876404 | P11: 27069 | Q11: 이상호(중) | S11: 설문내용 | T11: ACTH와 EDTA 검사 중복으로 나오는 경우 검체 하나로 보내고있음
B12: 충남 | C12: 세종(출) | D12: 유앤이내과 | E12: 25 | F12: 0 | I12: 경북 | J12: 경주 | K12: 굿모닝병원 | L12: 65 | M12: 63 | N12: =IFERROR((M12/L12)*100,) -> 96.923077 | P12: 33449 | Q12: 김현우 | S12: 설문내용 | T12: 바빠서 분리할 시간이 없다고 함
B13: 충남 | C13: 오창 | D13: 키우리소아청소년과의원 | E13: 305 | F13: 303 | I13: 영서 | J13: 원주 | K13: 명지병원(제천) | L13: 41 | M13: 39 | N13: =IFERROR((M13/L13)*100,) -> 95.121951 | P13: 39745 | Q13: 이문희
B14: 충남 | C14: 오창 | D14: 한국병원 | E14: 33 | F14: 0 | I14: 서울 | J14: 서울강남 | K14: 신사터미널마취통증의학과 | L14: 35 | M14: 35 | N14: =IFERROR((M14/L14)*100,) -> 100 | P14: 33781 | Q14: 이문희
B15: 충남 | C15: 천안 | D15: 이수내과의원 | E15: 14 | F15: 0 | I15: 서울 | J15: 서울중부 | K15: 서울케이(K)내과의원 | L15: 32 | M15: 27 | N15: =IFERROR((M15/L15)*100,) -> 84.375 | P15: 21965 | Q15: 장현우
B16: 충남 | C16: 홍성 | D16: 합덕서울내과의원 | E16: 3 | F16: 0 | I16: 경남 | J16: 부산남부 | K16: 한빛병원 | L16: 27 | M16: 27 | N16: =IFERROR((M16/L16)*100,) -> 100 | P16: 33554 | Q16: 김현우
B17: 경북 | C17: 경주 | D17: 바른몸의원 | E17: 136 | F17: 134 | I17: 경북 | J17: 대구남부 | K17: 청춘내과의원 | L17: 46 | M17: 18 | N17: =IFERROR((M17/L17)*100,) -> 39.130435 | P17: 14682 | Q17: 고진우
B18: 경북 | C18: 경주 | D18: 라임소아청소년과의원 | E18: 1 | F18: 1 | I18: 전북 | J18: 전북 | K18: 박은재 내과 | L18: 6 | M18: 6 | N18: =IFERROR((M18/L18)*100,) -> 100 | P18: 39016 | Q18: 김준
B19: 경북 | C19: 경주 | D19: 굿모닝병원 | E19: 7 | F19: 0 | I19: 경기 | J19: 김포 | K19: (의)성세의료재단뉴성민병원 | L19: 7 | M19: 5 | N19: =IFERROR((M19/L19)*100,) -> 71.428571
B20: 경북 | C20: 경주 | D20: 새천년병원 | E20: 4 | F20: 0 | I20: 경남 | J20: 부산서부 | K20: 의료법인 강혜의료재단 | L20: 5 | M20: 5 | N20: =IFERROR((M20/L20)*100,) -> 100
B21: 경북 | C21: 구미 | D21: 류마제일내과의원 | E21: 106 | F21: 0 | I21: 전남 | J21: 광주 | K21: 이현진신경과&김은정내과의원 | L21: 5 | M21: 5 | N21: =IFERROR((M21/L21)*100,) -> 100
B22: 경북 | C22: 구미 | D22: 바른유병원 | E22: 2 | F22: 0 | I22: 본원 | J22: QM팀 | K22: CAP 국외정도관리 | L22: 5 | M22: 5 | N22: =IFERROR((M22/L22)*100,) -> 100
B23: 경북 | C23: 김천(출) | D23: 현대내과의원 | E23: 1 | F23: 0 | I23: 전북 | J23: 전북 | K23: 효사랑전주요양병원 | L23: 4 | M23: 4 | N23: =IFERROR((M23/L23)*100,) -> 100
B24: 경북 | C24: 김천(출) | D24: 경상북도김천의료원 | E24: 25 | F24: 0 | I24: 전북 | J24: 전북 | K24: 우리내과의원 | L24: 27 | M24: 3 | N24: =IFERROR((M24/L24)*100,) -> 11.111111
B25: 경북 | C25: 김천(출) | D25: 김천제일병원 | E25: 23 | F25: 0 | I25: 서울 | J25: 서울강남 | K25: 트리니티여성의원 | L25: 11 | M25: 3 | N25: =IFERROR((M25/L25)*100,) -> 27.272727
B26: 경북 | C26: 대구남부 | D26: 청춘내과의원 | E26: 42 | F26: 19 | I26: 전북 | J26: 정읍 | K26: 정읍한국병원 | L26: 7 | M26: 3 | N26: =IFERROR((M26/L26)*100,) -> 42.857143
B27: 경북 | C27: 대구남부 | D27: 이상엽내과의원 | E27: 4 | F27: 4 | I27: 전북 | J27: 전북 | K27: 효사랑가족요양병원 | L27: 5 | M27: 3 | N27: =IFERROR((M27/L27)*100,) -> 60
B28: 경북 | C28: 대구남부 | D28: 구평리외과 | E28: 1 | F28: 1 | I28: 경남 | J28: 진주 | K28: 센텀병원 | L28: 3 | M28: 3 | N28: =IFERROR((M28/L28)*100,) -> 100
B29: 경북 | C29: 대구남부 | D29: 대구기독병원 | E29: 1 | F29: 0 | I29: 충남 | J29: 세종(출) | K29: 유앤이내과 | L29: 29 | M29: 2 | N29: =IFERROR((M29/L29)*100,) -> 6.8965517
B30: 경북 | C30: 대구남부 | D30: 범어샘편한내과 | E30: 3 | F30: 0 | I30: 경북 | J30: 대구남부 | K30: 용각의료재단 한신병원 | L30: 22 | M30: 2 | N30: =IFERROR((M30/L30)*100,) -> 9.0909091
... B154: 제주 | C154: 제주 | D154: 의료법인중앙의료재단중앙병원 | E154: 3 | F154: 0 | I154: 경남 | J154: 창원 | K154: YONSEI S HOSPITAL | L154: 3 | M154: 0 | N154: =IFERROR((M154/L154)*100,) -> 0
I155: 제주 | J155: 제주 | K155: 제주의료원 부속 요양병원 | L155: 3 | M155: 0 | N155: =IFERROR((M155/L155)*100,) -> 0
I156: 충북 | J156: 청주 | K156: 서원요양병원 | L156: 3 | M156: 0 | N156: =IFERROR((M156/L156)*100,) -> 0
I157: 서울 | J157: 서울남부 | K157: 덕산속조은내과의원 | L157: 3 | M157: 0 | N157: =IFERROR((M157/L157)*100,) -> 0
I158: 충남 | J158: 대전 | K158: 한일병원(신탄진) | L158: 3 | M158: 0 | N158: =IFERROR((M158/L158)*100,) -> 0
I159: 충남 | J159: 홍성 | K159: 의)정빈 합덕아산병원 | L159: 3 | M159: 0 | N159: =IFERROR((M159/L159)*100,) -> 0
I160: 충북 | J160: 청주 | K160: 참사랑병원 | L160: 3 | M160: 0 | N160: =IFERROR((M160/L160)*100,) -> 0
I161: 충남 | J161: 대전 | K161: 하나로의원 | L161: 2 | M161: 0 | N161: =IFERROR((M161/L161)*100,) -> 0
I162: 경북 | J162: 대구서부 | K162: 더나은병원 | L162: 2 | M162: 0 | N162: =IFERROR((M162/L162)*100,) -> 0
I163: 경북 | J163: 대구중부 | K163: 강남병원 | L163: 2 | M163: 0 | N163: =IFERROR((M163/L163)*100,) -> 0
I164: 서울 | J164: 서울강동 | K164: 연세무척나은병원 | L164: 2 | M164: 0 | N164: =IFERROR((M164/L164)*100,) -> 0
I165: 서울 | J165: 서울북부 | K165: 진접 한양병원 | L165: 2 | M165: 0 | N165: =IFERROR((M165/L165)*100,) -> 0
I166: 서울 | J166: 서울서부 | K166: 참요양병원 | L166: 2 | M166: 0 | N166: =IFERROR((M166/L166)*100,) -> 0
...

Sheet 5.대시보드
F2: 냉동검체(Plasma_ACTH) 부적합률 (2023년 03월 ~ 2023년 03월)
R10: 1 | S10: =IFERROR('3.피봇'!T6,"") -> 명지병원(제천)
R11: 2 | S11: =IFERROR('3.피봇'!T7,"") -> 이봉휘내과의원
R12: 3 | S12: =IFERROR('3.피봇'!T8,"") -> 건국대학교충주병원
R13: 4 | S13: =IFERROR('3.피봇'!T9,"") -> 원주의료원
R14: 5 | S14: =IFERROR('3.피봇'!T10,"") -> 총합계
R15: 6 | S15: =IFERROR('3.피봇'!T11,"") -> 0
R16: 7 | S16: =IFERROR('3.피봇'!T12,"") -> 0
R17: 8 | S17: =IFERROR('3.피봇'!T13,"") -> 0
R18: 9 | S18: =IFERROR('3.피봇'!T14,"") -> 0
R19: 10 | S19: =IFERROR('3.피봇'!T15,"") -> 0
R20: 11 | S20: =IFERROR('3.피봇'!T16,"") -> 0
R21: 12 | S21: =IFERROR('3.피봇'!T17,"") -> 0
... R25: 16 | S25: =IFERROR('3.피봇'!T21,"") -> 0

Sheet Sheet2
B2: 1 | C2: 키우리소아청소년과의원 | G2: 기타내용 | H2: ACTH : Plasma분리후 냉동으로 보내드려야하나 여건이 되지 않아 EDTA W/B로 해주세요. | Q2: 키우리소아청소년과의원
B3: 2 | C3: 바른몸의원 | G3: 기타내용 | H3: EDTA whole blood 올립니다. /ACTH를 EDTA로 올립니다. | Q3: 바른몸의원
B4: 3 | C4: 인천터미널 정형외과의원 | G4: 설문내용 | H4: 업무량이 많다는 이유로 검체 분리를 실시하지 않음 | Q4: 인천터미널 정형외과의원
B5: 4 | C5: 바른키움소아청소년과의원 | G5: 기타내용 | H5: ACTH 검체 EDTA로 보냈습니다. | Q5: 울산병원
B6: 5 | C6: 울산병원 | G6: 설문내용 | H6: 거래처에서 채취 즉시 또는 냉동되기전 거래처 방문을 요청함 | Q6: 바른키움소아청소년과의원
B7: 6 | C7: 서울케이(K)내과의원 | G7: 설문내용 | H7: ACTH와 EDTA 검사 중복으로 나오는 경우 검체 하나로 보내고있음 | Q7: 서울케이(K)내과의원
B8: 7 | C8: 청춘내과의원 | G8: 설문내용 | H8: 바빠서 분리할 시간이 없다고 함 | Q8: 청춘내과의원
B9: 8 | C9: 명지병원(제천) | Q9: 명지병원(제천)
B10: 9 | C10: 트리니티여성의원 | Q10: 대구보훈병원
B11: 10 | C11: 우리내과의원 | G11: 기타내용 | H11: 검체는 EDTA W/B 입니다 20번붙여서 올립니다. | Q11: 우리내과의원
B12: 11 | C12: SAM CHEON PO JEIL HOSPITAL | Q12: 트리니티여성의원
B13: 12 | C13: 강문호내과 | Q13: SAM CHEON PO JEIL HOSPITAL
B14: 13 | C14: 정읍한국병원 | Q14: 의료법인 소화병원
B15: 14 | C15: 좋은내과 | G15: 기타내용 | H15: 병원에서 환자사정으로 acth 샘플을 따로 채혈을 못해 cbc 검체로 검사진행 부탁드립니다 | Q15: 강문호내과
I17: 1. 왼쪽 검체렉의 경우 냉동으로 도착하여 전달된 검체
I18: 2. 오른쪽 검체렉의 경우 Plasma로 분리없이 검사팀으로 원심분리 후 전달 (변경사유: 혈청분리관을 사용하여 분리하였으나 기술부족으로 중지 요청)
I33: 3. 울산병원: 10mL EDTA 사용, 핵의학 검사 있으나 검체 공유 안함
I47: 4. 키우리소아청소년과의원: 진단혈액 (CBC, HbA1c) 검사 후 전달, 바코드 2개 사용 (20 => 40)
I63: 5. 바른몸의원: 검체량 매우 적음, 연속검사(LH, FSH) 시행

Sheet 담당자
A1: *ID | B1: 거래처명 | C1: 영업소명 | D1: 거래처에서는 담당직원에게 어떤 상태의 검체를 전달합니까? | E1: 기타 | F1: 거래처에서는 검사전까지 지켜져야하는 운반상태(검체 안정성)에 대한 내용을 알고 있습니까? | G1: 기타 | H1: 거래처에서 운반상태(검체 안정성)을 지키지 못하는 이유는 무엇입니까? (중복 선택 가능) | I1: 기타 | J1: 담당직원은 냉동검체 운반을 위하여 사용하는 별도의 검체 용기와 냉매가 있습니까? | K1: 기타 | L1: 거래처에서 영업소로 운반하기까지 소요되는 시간은 얼마입니까? | M1: 부적합 검체를 전달받은 경우 처리 방법은 무엇입니까? | N1: 기타 | O1: 냉동 검체 운반 과정 개선을 위해 필요한 것은 무엇입니까? (중복 선택 가능) | P1: 텍스트 | Q1: 개선을 위한 의견 | R1: 등록일 | S1: 등록자 | T1: 수정일 | U1: 수정자
A2: 165746 | B2: 굿모닝병원 | C2: 경주고객지원센터 | D2: Plasma [냉장, 실온] | F2: 알고있다. | H2: 해당없음,기타 | I2: 검사실 내에서도 내용은 알고는 있지만, 병원내에서 검사가 가능하지만 수탁으로 샘플을 보내는 상황에 냉동까지 할 여력이 안된다고 하셨습니다. | J2: 기타 | K2: Plasma 분리 후 냉장 상태로 전달받음 | L2: 평균 4시간 이내 | M2: 해당없음 | O2: 교육자료 | Q2: 검체 안정성에 대한 교육자료 필요 | R2: 44776.391 | S2: 이상하 계약직 (shangha_lee@scllab.co.kr) | T2: 44776.392 | U2: 이상하 계약직 (shangha_lee@scllab.co.kr)
A3: 165956 | B3: 나누리 인천 주안병원 | C3: 인천 | D3: Plasma [냉동] | F3: 알고있다. | H3: 해당없음 | J3: 운송박스(도수용, 차량용) + 아이스 젤 | L3: 평균 4시간 이내 | M3: 해당없음 | O3: 운반용기 | Q3: https://smartstore.naver.com/easylong/products/6980909810?NaPm=ct%3Dl6ebk53k%7Cci%3Dc36e017975b8e1b8d69a94aef2c2dc921f179d19%7Ctr%3Dslsl%7Csn%3D4493780%7Chk%3D856aab70cc3c67810a278c5518ec6240b153cefd 해당 제품은 5w/DC5V 로 USB 전원으로 전원공급이 가능하여 차량에서나 보조배터리 전원으로 사용이 가능하고 사이즈가 작기때문에 공간을 차지하지않아 사용이 유용할것같습니다. 온도는 2~8'C 까지 낮출수 있어 얼음과 함께 보관한다면 냉동검체의 녹는 시간을 늦출수 있을것 같습니다. 배터리가 내장해 있는 제품도 있어 휴대도 가능합니다 | R3: 44777.412 | S3: 고진우 사원 (jinwoo_go@scllab.co.kr) | T3: 44777.412 | U3: 고진우 사원 (jinwoo_go@scllab.co.kr)
A4: 165706 | B4: 나누리수원병원 | C4: 수원북부 | D4: Plasma [냉동] | F4: 알고있다. | H4: 해당없음 | J4: 운송박스(도수용, 차량용) + 아이스 젤 | L4: 평균 4시간 이내 | M4: 영업소에서 검체를 분리, 본원으로 냉동 요청 | O4: 운반용기,냉매보급(드라이 아이스) | Q4: 냉동검체를 운반하기 위해선 냉매가 꼭 필요하고 냉매를 담을수 있는 용기도 필요합니다. | R4: 44775.809 | S4: 김광희 차장 (kkh5501@scllab.co.kr) | T4: 44775.809 | U4: 김광희 차장 (kkh5501@scllab.co.kr)
A5: 165910 | B5: 대구기독병원 | C5: 대구남부 | D5: Plasma [냉동] | F5: 알고있다. | H5: 해당없음 | J5: 운송박스(도수용, 차량용) + 아이스 젤 | L5: 평균 4시간 이상 | M5: 기타 | O5: 운반용기,냉매보급(드라이 아이스) | Q5: 씨젠의료재단의 냉동 아이스겔패드와 운송용기가 있으면 좋을듯 합니다. | R5: 44776.835 | S5: 정명기 차장 (9pelle9@scllab.co.kr) | T5: 44776.835 | U5: 정명기 차장 (9pelle9@scllab.co.kr)
A6: 165755 | B6: 대구보훈병원 | C6: 대구서부 | D6: Whole Blood [냉장, 실온] | F6: 모르고있다. | H6: 해당없음,기타 | I6: 검체 관리담당 부재 | J6: 운송박스(도수용, 차량용) + 아이스 젤 | L6: 평균 2시간 이내 | M6: 해당없음 | O6: 운반용기 | Q6: 냉동검체 전용 작은 도수용 가방 및 운반 용기 영업소 보급 | R6: 44776.405 | S6: 서명교 차장 (kyo0327@scllab.co.kr) | T6: 44776.405 | U6: 서명교 차장 (kyo0327@scllab.co.kr)
A7: 165364 | B7: 드림요양병원(033071) | C7: 송파 | D7: Plasma [냉동] | F7: 알고있다. | H7: 해당없음 | J7: 운송박스(도수용, 차량용) + 드라이 아이스 | L7: 평균 2시간 이내 | M7: 해당없음 | O7: 운반용기 | Q7: 냉동검체 운송 담당자는 드라이아이스 넣은 아이스박스 구비하여야 함. *송파 운반로이첸 ICEPIA 핸들 아이스박스 6L 구비 하고 있습니다. | R7: 44774.42 | S7: 김지환(송) 사원 (jihwan_kim@scllab.co.kr) | T7: 44774.42 | U7: 김지환(송) 사원 (jihwan_kim@scllab.co.kr)
A8: 165911 | B8: 서대구대동병원 | C8: 대구남부 | D8: Plasma [냉동] | F8: 알고있다. | H8: 해당없음,기타 | J8: 운송박스(도수용, 차량용) + 아이스 젤 | L8: 평균 4시간 이상 | M8: 해당없음 | O8: 운반용기,냉매보급(드라이 아이스) | Q8: 씨젠의료재단의 냉동 아이스겔패드와 운송용기가 있으면 좋을듯 합니다. | R8: 44776.837 | S8: 정명기 차장 (9pelle9@scllab.co.kr) | T8: 44776.837 | U8: 정명기 차장 (9pelle9@scllab.co.kr)
A9: 166540 | B9: 서울케이(K)내과의원 | C9: 서울중부 | D9: Whole Blood [냉장, 실온] | F9: 알고있다. | H9: 해당없음,기타 | I9: ACTH와 EDTA 검사 중복으로 나오는 경우 검체 하나로 보내고있음 | J9: 운송박스(도수용, 차량용) + 드라이 아이스 | L9: 평균 2시간 이내 | M9: 본원으로 검체 분리, 냉동 요청 | O9: 해당없음 | Q9: 거래처에 분리후 냉동 요청 하겠습니다. | R9: 44781.811 | S9: 신기철 대리 (kichul_shin@scllab.co.kr) | T9: 44781.811 | U9: 신기철 대리 (kichul_shin@scllab.co.kr)
A10: 165395 | B10: 에덴요양병원 | C10: 서울강동 | D10: Plasma [냉동] | F10: 알고있다. | H10: 해당없음 | J10: 보온/보냉박스(텀블러 등) + 드라이 아이스 | L10: 평균 4시간 이내 | M10: 해당없음 | O10: 해당없음 | Q10: 운반을 위한 적절한 크기의 용기 제작 희망함(직원들이 소지하기에 적절한 크기) | R10: 44774.478 | S10: 박수현 차장 (tulip1052@scllab.co.kr) | T10: 44774.478 | U10: 박수현 차장 (tulip1052@scllab.co.kr)
A11: 165913 | B11: 용각의료재단 한신병원 | C11: 대구남부 | D11: Plasma [냉동] | F11: 알고있다. | H11: 해당없음 | J11: 운송박스(도수용, 차량용) + 아이스 젤 | L11: 평균 4시간 이상 | M11: 본원으로 검체 분리, 냉동 요청 | O11: 냉매보급(드라이 아이스),냉동고 | Q11: 냉동검체를 운반 할 수 있는 냉동보관용기가 필요합니다. | R11: 44776.849 | S11: 김성주 대리 (seoungju_kim@scllab.co.kr) | T11: 44776.849 | U11: 김성주 대리 (seoungju_kim@scllab.co.kr)
A12: 165766 | B12: 울산병원 | C12: 울산중부 | D12: Whole Blood [냉장, 실온] | F12: 모르고있다. | H12: 거래처에서 채취 즉시 또는 냉동되기전 거래처 방문을 요청함 | J12: 운송박스(도수용, 차량용) + 아이스 젤 | L12: 평균 4시간 이상 | M12: 본원으로 검체 분리, 냉동 요청 | O12: 교육자료,운반용기 | Q12: EDTA의 크기가 크지않은 만큼 적당한 소형크기의 운반용기가 있으면 좋을 듯합니다. | R12: 44776.43 | S12: 김필수 대리 (pilsu_kim@scllab.co.kr) | T12: 44776.43 | U12: 김필수 대리 (pilsu_kim@scllab.co.kr)
A13: 166388 | B13: 유앤이내과 | C13: 세종 | D13: Plasma [냉동] | F13: 알고있다. | H13: 해당없음 | J13: 운송박스(도수용, 차량용) + 아이스 젤 | L13: 평균 4시간 이상 | M13: 영업소에서 검체를 분리, 본원으로 냉동 요청 | O13: 운반용기,냉매보급(드라이 아이스),원심분리기 | Q13: 1> 영업사원에 맞춤제작형 운송용기 지급 ( 아이스겔이나 냉매제가 적재되어 편하게 운송하기 좋은 크기의 운송용기) 2> 통상에 전용 냉매제 칸을 만들어 본사에서 매일 냉매제 수급 및 관리체계 확립 | R13: 44781.407 | S13: 이태진 차장 (ltj3949@scllab.co.kr) | T13: 44781.407 | U13: 이태진 차장 (ltj3949@scllab.co.kr)
A14: 165775 | B14: 의료법인 소화병원 | C14: 서울중부 | D14: Plasma [냉장, 실온] | F14: 알고있다. | H14: 거래처에서 채취 즉시 또는 냉동되기전 거래처 방문을 요청함 | J14: 운송박스(도수용, 차량용) + 드라이 아이스 | L14: 평균 4시간 이내 | M14: 본원으로 검체 분리 요청 | O14: 교육자료 | Q14: 담당자가 알기쉬운 운반과정 밑 검사 방법을 정리한 교육자료를 통해 담당자가 충분히 인지하여 거래처에도 내용 전달하는게 좋을거같습니다. | R14: 44776.443 | S14: 강영재 사원 (yeongjae_kang@scllab.co.kr) | T14: 44776.443 | U14: 강영재 사원 (yeongjae_kang@scllab.co.kr)
A15: 165603 | B15: 인천터미널정형외과 | C15: 인천고객지원센터 | D15: Whole Blood [선행 검사 있음] | F15: 알고있다. | H15: 해당없음,기타 | I15: 업무량이 많다는 이유로 검체 분리를 실시하지 않음 | J15: 보온/보냉박스(텀블러 등) + 아이스 젤 | L15: 평균 4시간 이상 | M15: 해당없음 | O15: 교육자료,운반용기,냉매보급(드라이 아이스) | Q15: 냉동 유지에 필요한 전용 운반용기 및 냉매보급 | R15: 44775.496 | S15: 유영춘 대리 (youngchun_yu@scllab.co.kr) | T15: 44775.496 | U15: 유영춘 대리 (youngchun_yu@scllab.co.kr)
A16: 165369 | B16: 청춘내과 | C16: 대구남부 | D16: Whole Blood [냉장, 실온] | F16: 알고있다. | H16: 해당없음,기타 | I16: 청춘내과 임병 담당자에게 즉시 분리해줘야된다고 이야기했으나 처리하지 아니하며 바빠서 분리할 시간이 없다고 함 | J16: 운송박스(도수용, 차량용) + 드라이 아이스 | L16: 평균 2시간 이내 | M16: 본원으로 검체 분리, 냉동 요청 | O16: 냉동고 | Q16: 여름에는 드라이 아이스나,아이스겔 경우 오후쯤에 녹아내려 서늘함은 유지가 되지만 냉동검체는 녹아내림 차량용 냉동고가 있으면 냉동검체를 냉동상태로 운반가능할것으로 보임 | R16: 44774.431 | S16: 전재훈 주임 (jaehoon_june@scllab.co.kr) | T16: 44774.431 | U16: 전재훈 주임 (jaehoon_june@scllab.co.kr)
A17: 165908 | B17: 한성재단동아메디병원 | C17: 대구남부 | D17: 기타 | E17: Plasma [냉동,냉장] | F17: 알고있다. | H17: 거래처에서 채취 즉시 또는 냉동되기전 거래처 방문을 요청함,기타 | I17: 즉시 분리해서 바로 주는경우 | J17: 운송박스(도수용, 차량용) + 아이스 젤 | L17: 평균 4시간 이상 | M17: 해당없음 | O17: 운반용기,냉동고 | Q17: 여름 같은 경우 차량용 냉동고가 필요합니다. | R17: 44776.826 | S17: 김상우 대리 (sangwoo_kim@scllab.co.kr) | T17: 44776.838 | U17: 김상우 대리 (sangwoo_kim@scllab.co.kr)
A18: 165584 | B18: 한솔요양병원 | C18: 대구서부고객지원센터 | D18: Whole Blood [냉장, 실온] | F18: 알고있다. | H18: 기타 | I18: 검체 분리와 냉동 과정의 번거로움 때문에 실시하지 않음 | J18: 운송박스(도수용, 차량용) + 아이스 젤 | L18: 평균 2시간 이내 | M18: 본원으로 검체 분리, 냉동 요청 | O18: 교육자료,운반용기,냉매보급(드라이 아이스) | Q18: 1. 병원에 전달가능한 교육자료 배포 2. 소량의 냉동검체 운반을 위한 운반용기 제작 3. 운반용기 크기에 맞는 소분화된 냉매 보급 | R18: 44775.442 | S18: 고동성 대리 (gdsng@scllab.co.kr) | T18: 44775.442 | U18: 고동성 대리 (gdsng@scllab.co.kr)
A19: 165440 | B19: 현대요양병원 | C19: 영서2 | D19: Plasma [냉장, 실온] | F19: 알고있다. | H19: 해당없음,거래처에서 채취 즉시 또는 냉동되기전 거래처 방문을 요청함 | J19: 운송박스(도수용, 차량용) + 드라이 아이스 | L19: 평균 1시간 이내 | M19: 영업소에서 검체를 분리, 냉동 | O19: 검사 거절(부적합 처리),교육자료 | Q19: 적절한 운반용기 필요 | R19: 44774.661 | S19: 황병준 지사장 (hbj@scllab.co.kr) | T19: 44774.661 | U19: 황병준 지사장 (hbj@scllab.co.kr)
A20: 165952 | B20: 현대의원(동춘동) | C20: 인천 | D20: Plasma [냉장, 실온] | F20: 알고있다. | H20: 거래처에서 채취 즉시 또는 냉동되기전 거래처 방문을 요청함 | J20: 운송박스(도수용, 차량용) + 아이스 젤 | L20: 평균 4시간 이내 | M20: 본원으로 검체 분리, 냉동 요청 | O20: 운반용기,냉매보급(드라이 아이스) | Q20: 냉동상태 지속유지를 위한 드라이아이스 및 냉동전용 운반용기(ex)바이오덤 5시리즈 등) 필요 | R20: 44777.402 | S20: 장현우 사원 (hyeonwoo_jang2@scllab.co.kr) | T20: 44777.402 | U20: 장현우 사원 (hyeonwoo_jang2@scllab.co.kr)
